Workbook

Sheet README
A1: TFS Dashboard 2.0 — Upload Workbook (aligned to Odoo extract 004)
A3: MONTHLY REFRESH — 3 steps:
A4: 1. Run extract 004 in Odoo. Delete old rows in RAW_004 (keep row 1), then paste the new export's rows
A5: (all 13 columns, without the header row) starting at cell A2. Column N fills in automatically.
A6: 2. Open UPLOAD. If the CHECKS block flags a mismatch, it usually means new staff/project/month
A7: combinations appeared: add the missing rows in ALLOCATIONS and/or MAPPING until all checks say OK.
A8: 3. Export the UPLOAD tab (File > Save As > CSV while on the UPLOAD tab) and upload it to the TFS Dashboard.
A10: TAB GUIDE:
A11: RAW_004 Paste target for the raw Odoo export. Columns must stay in Odoo's order:
A12: Created by | Date | Description | Employee | Last Updated by | Last Updated on |
A13: Parent Task | Project | Quantity | Sales Order Item | Task | Billable | Billable Type
A14: ALLOCATIONS One row per staff x project x month. Fill the yellow 'Allocated Hours' column with planned
... A26: and re-export rather than editing this workbook.

Sheet RAW_004
A1: Created by | B1: Date | C1: Description | D1: Employee | E1: Last Updated by | F1: Last Updated on | G1: Parent Task | H1: Project | I1: Quantity | J1: Sales Order Item | K1: Task | L1: Billable | M1: Billable Type | N1: Month (auto)
A2: Augustus Asamoah | B2: 46213 | C2: / | D2: Augustus Asamoah | E2: Augustus Asamoah | F2: 46210.376 | H2: P13PC00A00 - Private Sector Companies | I2: 0 | K2: Seedling Procurement and Supply | L2: FALSE | M2: Non-Billable | N2: =IF(B2="","",IF(ISNUMBER(B2),TEXT(B2,"YYYY-MM"),LEFT(B2,7)))
A3: Augustus Asamoah | B3: 46213 | C3: / | D3: Augustus Asamoah | E3: Augustus Asamoah | F3: 46210.376 | H3: P13QC00A00 - EFI Programme | I3: 0 | K3: Seedling Procurement and Supply | L3: FALSE | M3: Non-Billable | N3: =IF(B3="","",IF(ISNUMBER(B3),TEXT(B3,"YYYY-MM"),LEFT(B3,7)))
A4: Augustus Asamoah | B4: 46213 | C4: / | D4: Augustus Asamoah | E4: Augustus Asamoah | F4: 46210.376 | H4: P13NC00A00 - WALMART II | I4: 0 | K4: Check in call with Simon | L4: FALSE | M4: Non-Billable | N4: =IF(B4="","",IF(ISNUMBER(B4),TEXT(B4,"YYYY-MM"),LEFT(B4,7)))
A5: Augustus Asamoah | B5: 46213 | C5: / | D5: Augustus Asamoah | E5: Augustus Asamoah | F5: 46210.376 | H5: P13QC00A00 - EFI Programme | I5: 0 | K5: Review meeting and launch of tree planting in Takoradi | L5: FALSE | M5: Non-Billable | N5: =IF(B5="","",IF(ISNUMBER(B5),TEXT(B5,"YYYY-MM"),LEFT(B5,7)))
A6: Augustus Asamoah | B6: 46212 | C6: / | D6: Augustus Asamoah | E6: Augustus Asamoah | F6: 46210.376 | H6: P13QC00A00 - EFI Programme | I6: 0 | K6: Review meeting and launch of tree planting in Takoradi | L6: FALSE | M6: Non-Billable | N6: =IF(B6="","",IF(ISNUMBER(B6),TEXT(B6,"YYYY-MM"),LEFT(B6,7)))
A7: Augustus Asamoah | B7: 46211 | C7: / | D7: Augustus Asamoah | E7: Augustus Asamoah | F7: 46210.376 | H7: P13QC00A00 - EFI Programme | I7: 0 | K7: Review meeting and launch of tree planting in Takoradi | L7: FALSE | M7: Non-Billable | N7: =IF(B7="","",IF(ISNUMBER(B7),TEXT(B7,"YYYY-MM"),LEFT(B7,7)))
A8: Ekow Nyamekye Tawiah | B8: 46210 | C8: Proposal for BUA Bonsucro CHoC Standard | D8: Ekow Nyamekye Tawiah | E8: Ekow Nyamekye Tawiah | F8: 46210.653 | H8: Non-Billable Tasks | I8: 0 | K8: Business Development and Networking | L8: FALSE | M8: Non-Billable | N8: =IF(B8="","",IF(ISNUMBER(B8),TEXT(B8,"YYYY-MM"),LEFT(B8,7)))
A9: Ekow Nyamekye Tawiah | B9: 46210 | C9: Data review and reporting framework | D9: Ekow Nyamekye Tawiah | E9: Ekow Nyamekye Tawiah | F9: 46210.648 | H9: PCGH738 | I9: 1 | J9: PCGH738 - Analysis and Reporting (3) (Barnsley International Limited) | K9: Analysis and Reporting (3) | L9: TRUE | M9: Billed at a Fixed price | N9: =IF(B9="","",IF(ISNUMBER(B9),TEXT(B9,"YYYY-MM"),LEFT(B9,7)))
A10: Ekow Nyamekye Tawiah | B10: 46210 | C10: Annual Review with line Manager | D10: Ekow Nyamekye Tawiah | E10: Ekow Nyamekye Tawiah | F10: 46210.644 | H10: Non-Billable Tasks | I10: 0 | K10: Line Management | L10: FALSE | M10: Non-Billable | N10: =IF(B10="","",IF(ISNUMBER(B10),TEXT(B10,"YYYY-MM"),LEFT(B10,7)))
A11: Augustus Asamoah | B11: 46210 | C11: / | D11: Augustus Asamoah | E11: Augustus Asamoah | F11: 46210.376 | H11: P13QC00A00 - EFI Programme | I11: 0 | K11: Review meeting and launch of tree planting in Takoradi | L11: FALSE | M11: Non-Billable | N11: =IF(B11="","",IF(ISNUMBER(B11),TEXT(B11,"YYYY-MM"),LEFT(B11,7)))
A12: Augustus Asamoah | B12: 46210 | C12: / | D12: Augustus Asamoah | E12: Augustus Asamoah | F12: 46210.373 | H12: P13QC00A00 - EFI Programme | I12: 0 | K12: Follow up on field wrok and related activities | L12: FALSE | M12: Non-Billable | N12: =IF(B12="","",IF(ISNUMBER(B12),TEXT(B12,"YYYY-MM"),LEFT(B12,7)))
A13: Augustus Asamoah | B13: 46210 | C13: / | D13: Augustus Asamoah | E13: Augustus Asamoah | F13: 46210.376 | H13: P13PC00A00 - Private Sector Companies | I13: 0 | K13: coordination of MTS and related Activities | L13: FALSE | M13: Non-Billable | N13: =IF(B13="","",IF(ISNUMBER(B13),TEXT(B13,"YYYY-MM"),LEFT(B13,7)))
A14: Augustus Asamoah | B14: 46210 | C14: / | D14: Augustus Asamoah | E14: Augustus Asamoah | F14: 46210.376 | H14: P13NC00A00 - WALMART II | I14: 0 | K14: Check in call with Simon | L14: FALSE | M14: Non-Billable | N14: =IF(B14="","",IF(ISNUMBER(B14),TEXT(B14,"YYYY-MM"),LEFT(B14,7)))
A15: Augustus Asamoah | B15: 46210 | C15: / | D15: Augustus Asamoah | E15: Augustus Asamoah | F15: 46210.376 | H15: P13NC00A00 - WALMART II | I15: 0 | K15: RSC Procurements | L15: FALSE | M15: Non-Billable | N15: =IF(B15="","",IF(ISNUMBER(B15),TEXT(B15,"YYYY-MM"),LEFT(B15,7)))
A16: Augustus Asamoah | B16: 46210 | C16: / | D16: Augustus Asamoah | E16: Augustus Asamoah | F16: 46210.376 | H16: P13PC00A00 - Private Sector Companies | I16: 0 | K16: Support for A-A HMB | L16: FALSE | M16: Non-Billable | N16: =IF(B16="","",IF(ISNUMBER(B16),TEXT(B16,"YYYY-MM"),LEFT(B16,7)))
A17: Augustus Asamoah | B17: 46210 | C17: / | D17: Augustus Asamoah | E17: Augustus Asamoah | F17: 46210.366 | H17: P13PC00A00 - Private Sector Companies | I17: 0 | K17: Seedling Procurement and Supply | L17: FALSE | M17: Non-Billable | N17: =IF(B17="","",IF(ISNUMBER(B17),TEXT(B17,"YYYY-MM"),LEFT(B17,7)))
A18: Augustus Asamoah | B18: 46210 | C18: / | D18: Augustus Asamoah | E18: Augustus Asamoah | F18: 46210.365 | H18: P13QC00A00 - EFI Programme | I18: 0 | K18: Seedling Procurement and Supply | L18: FALSE | M18: Non-Billable | N18: =IF(B18="","",IF(ISNUMBER(B18),TEXT(B18,"YYYY-MM"),LEFT(B18,7)))
A19: Augustus Asamoah | B19: 46210 | C19: / | D19: Augustus Asamoah | E19: Augustus Asamoah | F19: 46210.364 | H19: P13NC00A00 - WALMART II | I19: 0 | K19: Seedling Procurement and Supply for MTS | L19: FALSE | M19: Non-Billable | N19: =IF(B19="","",IF(ISNUMBER(B19),TEXT(B19,"YYYY-MM"),LEFT(B19,7)))
A20: Augustus Asamoah | B20: 46210 | C20: / | D20: Augustus Asamoah | E20: Augustus Asamoah | F20: 46210.364 | H20: P13NC00A00 - WALMART II | I20: 0 | K20: Seedling Procurement and Supply for MTS | L20: FALSE | M20: Non-Billable | N20: =IF(B20="","",IF(ISNUMBER(B20),TEXT(B20,"YYYY-MM"),LEFT(B20,7)))
A21: Ekow Nyamekye Tawiah | B21: 46209 | C21: / | D21: Ekow Nyamekye Tawiah | E21: Ekow Nyamekye Tawiah | F21: 46210.653 | H21: Non-Billable Tasks | I21: 2.5 | K21: Business Development and Networking | L21: FALSE | M21: Non-Billable | N21: =IF(B21="","",IF(ISNUMBER(B21),TEXT(B21,"YYYY-MM"),LEFT(B21,7)))
... A27: Augustus Asamoah | B27: 46209 | C27: / | D27: Augustus Asamoah | E27: Augustus Asamoah | F27: 46210.376 | H27: P13NC00A00 - WALMART II | I27: 0 | K27: Seedling Procurement and Supply for MTS | L27: FALSE | M27: Non-Billable | N27: =IF(B27="","",IF(ISNUMBER(B27),TEXT(B27,"YYYY-MM"),LEFT(B27,7)))
A28: Ekow Nyamekye Tawiah | B28: 46209 | C28: Review and Rerun of Reunion Deforestation Risk Analysis. | D28: Ekow Nyamekye Tawiah | E28: Ekow Nyamekye Tawiah | F28: 46209.382 | H28: PCGH778 - General Support | I28: 0 | J28: PCGH778 - Support to Other Workstreams (3) (Proforest Limited(PCUK GBP)) | K28: (WS3: Deforestation) Deforestation Remote Risk Assessment | L28: TRUE | M28: Billed at a Fixed price | N28: =IF(B28="","",IF(ISNUMBER(B28),TEXT(B28,"YYYY-MM"),LEFT(B28,7)))
A29: Ekow Nyamekye Tawiah | B29: 46209 | C29: Republic Day | D29: Ekow Nyamekye Tawiah | E29: Ekow Nyamekye Tawiah | F29: 46209.38 | H29: Non-Billable Tasks | I29: 0 | K29: Public Holiday | L29: FALSE | M29: Non-Billable | N29: =IF(B29="","",IF(ISNUMBER(B29),TEXT(B29,"YYYY-MM"),LEFT(B29,7)))
A30: Abel Ansu | B30: 46206 | C30: Supply of seedlings from Gambia to Bitre and Biaso Kasapin | D30: Abel Ansu | E30: Abel Ansu | F30: 46210.372 | H30: P13PC00A00 - Private Sector Companies | I30: 8 | K30: Personnel Cost | L30: FALSE | M30: Non-Billable | N30: =IF(B30="","",IF(ISNUMBER(B30),TEXT(B30,"YYYY-MM"),LEFT(B30,7)))
A31: Ekow Nyamekye Tawiah | B31: 46206 | C31: / | D31: Ekow Nyamekye Tawiah | E31: Ekow Nyamekye Tawiah | F31: 46209.38 | H31: Non-Billable Tasks | I31: 4 | K31: Public Holiday | L31: FALSE | M31: Non-Billable | N31: =IF(B31="","",IF(ISNUMBER(B31),TEXT(B31,"YYYY-MM"),LEFT(B31,7)))
A32: Stephen Doso | B32: 46206 | C32: / | D32: Stephen Doso | E32: Stephen Doso | F32: 46209.346 | H32: Non-Billable Tasks | I32: 8 | K32: Public Holiday | L32: FALSE | M32: Non-Billable | N32: =IF(B32="","",IF(ISNUMBER(B32),TEXT(B32,"YYYY-MM"),LEFT(B32,7)))
A33: Louis Defo | B33: 46206 | C33: Go the Dja et Lobo division for some stakeholders engagaments | D33: Louis Defo | E33: Louis Defo | F33: 46209.315 | H33: PCGH787 | I33: 8 | J33: PCGH787 - Desk Study (3) (Proforest Limited(PCUK GBP)) | L33: TRUE | M33: Billed at a Fixed price | N33: =IF(B33="","",IF(ISNUMBER(B33),TEXT(B33,"YYYY-MM"),LEFT(B33,7)))
A34: Abel Ansu | B34: 46205 | C34: Monitoring of lining and pegging | D34: Abel Ansu | E34: Abel Ansu | F34: 46210.371 | H34: P13NC00A00 - WALMART II | I34: 8 | K34: Programme Personnel and Management | L34: FALSE | M34: Non-Billable | N34: =IF(B34="","",IF(ISNUMBER(B34),TEXT(B34,"YYYY-MM"),LEFT(B34,7)))
A35: Stephen Doso | B35: 46205 | C35: / | D35: Stephen Doso | E35: Stephen Doso | F35: 46209.542 | H35: PCGH775 - ESDD of Valency Operations for FMO | I35: 1 | J35: PCGH775 - Field Verification (2) (Valency International DMCC) | K35: Field verification and reporting in Nigeria (2) | L35: TRUE | M35: Billed at a Fixed price | N35: =IF(B35="","",IF(ISNUMBER(B35),TEXT(B35,"YYYY-MM"),LEFT(B35,7)))
A36: Stephen Doso | B36: 46205 | C36: / | D36: Stephen Doso | E36: Stephen Doso | F36: 46209.538 | H36: Non-Billable Tasks | I36: 1.5 | K36: Senior Management Activities | L36: FALSE | M36: Non-Billable | N36: =IF(B36="","",IF(ISNUMBER(B36),TEXT(B36,"YYYY-MM"),LEFT(B36,7)))
A37: Stephen Doso | B37: 46205 | C37: Dangote Sugar Call | D37: Stephen Doso | E37: Stephen Doso | F37: 46209.538 | H37: Non-Billable Tasks | I37: 0.5 | K37: Ad Hoc Time on Projects / Programmes | L37: FALSE | M37: Non-Billable | N37: =IF(B37="","",IF(ISNUMBER(B37),TEXT(B37,"YYYY-MM"),LEFT(B37,7)))
A38: Ekow Nyamekye Tawiah | B38: 46205 | C38: Deforestation Risk Analysis for Cameroon, Mauritius, Mozambique, Nigeria and Reunion (Run Analysis) | D38: Ekow Nyamekye Tawiah | E38: Ekow Nyamekye Tawiah | F38: 46209.387 | H38: PCGH778 - General Support | I38: 4 | J38: PCGH778 - Support to Other Workstreams (3) (Proforest Limited(PCUK GBP)) | K38: (WS3: Deforestation) Deforestation Remote Risk Assessment | L38: TRUE | M38: Billed at a Fixed price | N38: =IF(B38="","",IF(ISNUMBER(B38),TEXT(B38,"YYYY-MM"),LEFT(B38,7)))
A39: Ekow Nyamekye Tawiah | B39: 46205 | C39: / | D39: Ekow Nyamekye Tawiah | E39: Ekow Nyamekye Tawiah | F39: 46209.381 | H39: PCGH778 - General Support | I39: 0 | J39: PCGH778 - Support to Other Workstreams (3) (Proforest Limited(PCUK GBP)) | L39: TRUE | M39: Billed at a Fixed price | N39: =IF(B39="","",IF(ISNUMBER(B39),TEXT(B39,"YYYY-MM"),LEFT(B39,7)))
A40: Louis Defo | B40: 46205 | C40: participate to Cameroon cocoa week in order to do some stakeholdesr engagements | D40: Louis Defo | E40: Louis Defo | F40: 46209.314 | H40: PCGH787 | I40: 8 | J40: PCGH787 - Desk Study (3) (Proforest Limited(PCUK GBP)) | L40: TRUE | M40: Billed at a Fixed price | N40: =IF(B40="","",IF(ISNUMBER(B40),TEXT(B40,"YYYY-MM"),LEFT(B40,7)))
A41: Afua Serwah Akoto Prempeh | B41: 46205 | C41: Internal meeting to review feedback from TCI, agree on next steps, discuss meeting in Cameroon and provide input into brainstorming sessions. | D41: Afua Serwah Akoto Prempeh | E41: Afua Serwah Akoto Prempeh | F41: 46205.5 | H41: P23AC00C00 - FGMC | I41: 2 | L41: FALSE | M41: Non-Billable | N41: =IF(B41="","",IF(ISNUMBER(B41),TEXT(B41,"YYYY-MM"),LEFT(B41,7)))
A42: Ekow Nyamekye Tawiah | B42: 46204 | C42: / | D42: Ekow Nyamekye Tawiah | E42: Ekow Nyamekye Tawiah | F42: 46210.643 | H42: PCGH778 - General Support | I42: 4 | J42: PCGH778 - Support to Other Workstreams (3) (Proforest Limited(PCUK GBP)) | K42: (WS3: Deforestation) Deforestation Remote Risk Assessment | L42: TRUE | M42: Billed at a Fixed price | N42: =IF(B42="","",IF(ISNUMBER(B42),TEXT(B42,"YYYY-MM"),LEFT(B42,7)))
A43: Abel Ansu | B43: 46204 | C43: Supply of seedlings to Bitre/ Biaso Kasapin | D43: Abel Ansu | E43: Abel Ansu | F43: 46210.37 | H43: P13PC00A00 - Private Sector Companies | I43: 8 | K43: Personnel Cost | L43: FALSE | M43: Non-Billable | N43: =IF(B43="","",IF(ISNUMBER(B43),TEXT(B43,"YYYY-MM"),LEFT(B43,7)))
A44: Stephen Doso | B44: 46204 | C44: / | D44: Stephen Doso | E44: Stephen Doso | F44: 46209.537 | H44: PCGH738 | I44: 1.5 | J44: PCGH738 - Analysis and Reporting (3) (Barnsley International Limited) | K44: Analysis and Reporting (3) | L44: TRUE | M44: Billed at a Fixed price | N44: =IF(B44="","",IF(ISNUMBER(B44),TEXT(B44,"YYYY-MM"),LEFT(B44,7)))
A45: Stephen Doso | B45: 46204 | C45: / | D45: Stephen Doso | E45: Stephen Doso | F45: 46209.536 | H45: PCGH788 - CDC Boa & Mondoni CV-HCS Scoping | I45: 1 | J45: PCGH788 - Participatory mapping (CAMEROON DEVELOPMENT CORPORATION (CDC)) | K45: BOA: MAPPING AND REPORTING (2) | L45: TRUE | M45: Billed Manually | N45: =IF(B45="","",IF(ISNUMBER(B45),TEXT(B45,"YYYY-MM"),LEFT(B45,7)))
...

Sheet ALLOCATIONS
A1: Employee (Odoo name) | B1: Project (Odoo name) | C1: Month (YYYY-MM) | D1: Allocated Hours
A2: Afua Serwah Akoto Prempeh | B2: Non-Billable Tasks | C2: 2026-01
A3: Afua Serwah Akoto Prempeh | B3: P23AC00C00 - FGMC | C3: 2026-01
A4: Augustus Asamoah | B4: Non-Billable Tasks | C4: 2026-01
A5: Augustus Asamoah | B5: P13NC00A00 - WALMART II | C5: 2026-01
A6: Augustus Asamoah | B6: P13QC00A00 - EFI Programme | C6: 2026-01
A7: Augustus Asamoah | B7: PCGH769 | C7: 2026-01
A8: Augustus Asamoah | B8: PCGH771 | C8: 2026-01
A9: Clement Obeng-Manu | B9: Non-Billable Tasks | C9: 2026-01
A10: Clement Obeng-Manu | B10: PCGH722 | C10: 2026-01
A11: Clement Obeng-Manu | B11: PCGH752 | C11: 2026-01
A12: Clement Obeng-Manu | B12: PCGH769 | C12: 2026-01
A13: Daleba Bernard Kpenahi Raymond | B13: Non-Billable Tasks | C13: 2026-01
... A390: Stephen Doso | B390: PCGH788 - CDC Boa & Mondoni CV-HCS Scoping | C390: 2026-07

Sheet MAPPING
A1: EMPLOYEE MAPPING | E1: PROJECT MAPPING
A2: Odoo Employee Name | B2: Dashboard Staff ID | C2: Dashboard Staff Name | E2: Odoo Project Name | F2: Dashboard Project Name | G2: Program
A3: Abel Ansu | B3: STF-001 | C3: Abel Ansu | E3: Business and Project Management Training | F3: Business and Project Management Training
A4: Adwoa Fremah Ntosour-Amponsem | B4: STF-002 | C4: Adwoa Fremah Ntosour-Amponsem | E4: Global Internal Projects (GIPs) | F4: Global Internal Projects (GIPs)
A5: Afua Serwah Akoto Prempeh | B5: STF-003 | C5: Afua Serwah Akoto Prempeh | E5: Internal | F5: Internal
A6: Augustus Asamoah | B6: STF-004 | C6: Augustus Asamoah | E6: Non-Billable Tasks | F6: Non-Billable Tasks
A7: Clement Obeng-Manu | B7: STF-005 | C7: Clement Obeng-Manu | E7: P13GC00A00 - GAC Ulula | F7: GAC Ulula
A8: Daleba Bernard Kpenahi Raymond | B8: STF-006 | C8: Daleba Bernard Kpenahi Raymond | E8: P13LC00A00 - FAO Support in Cameroon | F8: FAO Support in Cameroon
A9: Ebenezer Gyadu | B9: STF-007 | C9: Ebenezer Gyadu | E9: P13NC00A00 - WALMART II | F9: WALMART II
A10: Ekow Nyamekye Tawiah | B10: STF-008 | C10: Ekow Nyamekye Tawiah | E10: P13PC00A00 - Private Sector Companies | F10: Private Sector Companies
A11: Ernestina Incoom | B11: STF-009 | C11: Ernestina Incoom | E11: P13QC00A00 - EFI Programme | F11: EFI Programme
A12: Frederick Antwi | B12: STF-010 | C12: Frederick Antwi | E12: P23AC00C00 - FGMC | F12: FGMC
A13: Helena Tetteh | B13: STF-011 | C13: Helena Tetteh | E13: PCGH686 | F13: PCGH686
A14: Jacqueline Nyakutse Afua | B14: STF-012 | C14: Jacqueline Nyakutse Afua | E14: PCGH722 | F14: PCGH722
... A25: Stephen Doso | B25: STF-023 | C25: Stephen Doso | E25: PCGH769 | F25: PCGH769
E26: PCGH771 | F26: PCGH771
E27: PCGH772 | F27: PCGH772
E28: PCGH774 -Evaluation Deep-Dive Action Plans by Socfin Group | F28: Evaluation Deep-Dive Action Plans by Socfin Group
E29: PCGH775 - ESDD of Valency Operations for FMO | F29: ESDD of Valency Operations for FMO
E30: PCGH776 - Deforestation Risk-Assessment Cashew-Coast | F30: Deforestation Risk-Assessment Cashew-Coast
E31: PCGH777 | F31: PCGH777
E32: PCGH778 - General Support | F32: General Support
E33: PCGH779 - Cote d'Ivoire） | F33: Cote d'Ivoire）
E34: PCGH780 - Nigeria | F34: Nigeria
E35: PCGH783 - Zimbabwe HRDD | F35: Zimbabwe HRDD
E36: PCGH784 | F36: PCGH784
E37: PCGH785 | F37: PCGH785
... E45: PCGH793 | F45: PCGH793

Sheet UPLOAD
A1: CHECKS (all must be OK before uploading)
A2: Total hours reconcile (RAW_004 = UPLOAD): | C2: =IF(ROUND(SUM(RAW_004!I2:I10001)-SUM(G8:G1007),2)=0,"OK","MISMATCH: "&TEXT(SUM(RAW_004!I2:I10001)-SUM(G8:G1007),"0.00")&" hrs not in UPLOAD - add missing rows in ALLOCATIONS")
A3: All employees mapped: | C3: =IF(SUMPRODUCT((RAW_004!D2:D10001<>"")*ISNA(MATCH(RAW_004!D2:D10001,MAPPING!A3:A302,0)))=0,"OK","UNMAPPED EMPLOYEES: add them in MAPPING")
A4: All projects mapped: | C4: =IF(SUMPRODUCT((RAW_004!H2:H10001<>"")*ISNA(MATCH(RAW_004!H2:H10001,MAPPING!E3:E302,0)))=0,"OK","UNMAPPED PROJECTS: add them in MAPPING")
A6: UPLOAD DATA - while on this tab, File > Save As > CSV, then upload the CSV to the TFS Dashboard
A7: Staff ID | B7: Staff Name | C7: Project | D7: Program | E7: Period | F7: Allocated Hours | G7: Actual Hours | H7: Variance (Actual - Allocated)
A8: =IF(ALLOCATIONS!A2="","",IFERROR(VLOOKUP(ALLOCATIONS!A2,MAPPING!$A$3:$C$302,2,FALSE),"UNMAPPED")) | B8: =IF(ALLOCATIONS!A2="","",IFERROR(VLOOKUP(ALLOCATIONS!A2,MAPPING!$A$3:$C$302,3,FALSE),ALLOCATIONS!A2)) | C8: =IF(ALLOCATIONS!A2="","",IFERROR(VLOOKUP(ALLOCATIONS!B2,MAPPING!$E$3:$G$302,2,FALSE),"UNMAPPED")) | D8: =IF(ALLOCATIONS!A2="","",IFERROR(IF(VLOOKUP(ALLOCATIONS!B2,MAPPING!$E$3:$G$302,3,FALSE)="","",VLOOKUP(ALLOCATIONS!B2,MAPPING!$E$3:$G$302,3,FALSE)),"")) | E8: =IF(ALLOCATIONS!A2="","",ALLOCATIONS!C2) | F8: =IF(ALLOCATIONS!A2="","",IF(ALLOCATIONS!D2="",0,ALLOCATIONS!D2)) | G8: =IF(ALLOCATIONS!A2="","",SUMIFS(RAW_004!$I$2:$I$10001,RAW_004!$D$2:$D$10001,ALLOCATIONS!A2,RAW_004!$H$2:$H$10001,ALLOCATIONS!B2,RAW_004!$N$2:$N$10001,ALLOCATIONS!C2)) | H8: =IF(A8="","",G8-F8)
A9: =IF(ALLOCATIONS!A3="","",IFERROR(VLOOKUP(ALLOCATIONS!A3,MAPPING!$A$3:$C$302,2,FALSE),"UNMAPPED")) | B9: =IF(ALLOCATIONS!A3="","",IFERROR(VLOOKUP(ALLOCATIONS!A3,MAPPING!$A$3:$C$302,3,FALSE),ALLOCATIONS!A3)) | C9: =IF(ALLOCATIONS!A3="","",IFERROR(VLOOKUP(ALLOCATIONS!B3,MAPPING!$E$3:$G$302,2,FALSE),"UNMAPPED")) | D9: =IF(ALLOCATIONS!A3="","",IFERROR(IF(VLOOKUP(ALLOCATIONS!B3,MAPPING!$E$3:$G$302,3,FALSE)="","",VLOOKUP(ALLOCATIONS!B3,MAPPING!$E$3:$G$302,3,FALSE)),"")) | E9: =IF(ALLOCATIONS!A3="","",ALLOCATIONS!C3) | F9: =IF(ALLOCATIONS!A3="","",IF(ALLOCATIONS!D3="",0,ALLOCATIONS!D3)) | G9: =IF(ALLOCATIONS!A3="","",SUMIFS(RAW_004!$I$2:$I$10001,RAW_004!$D$2:$D$10001,ALLOCATIONS!A3,RAW_004!$H$2:$H$10001,ALLOCATIONS!B3,RAW_004!$N$2:$N$10001,ALLOCATIONS!C3)) | H9: =IF(A9="","",G9-F9)
A10: =IF(ALLOCATIONS!A4="","",IFERROR(VLOOKUP(ALLOCATIONS!A4,MAPPING!$A$3:$C$302,2,FALSE),"UNMAPPED")) | B10: =IF(ALLOCATIONS!A4="","",IFERROR(VLOOKUP(ALLOCATIONS!A4,MAPPING!$A$3:$C$302,3,FALSE),ALLOCATIONS!A4)) | C10: =IF(ALLOCATIONS!A4="","",IFERROR(VLOOKUP(ALLOCATIONS!B4,MAPPING!$E$3:$G$302,2,FALSE),"UNMAPPED")) | D10: =IF(ALLOCATIONS!A4="","",IFERROR(IF(VLOOKUP(ALLOCATIONS!B4,MAPPING!$E$3:$G$302,3,FALSE)="","",VLOOKUP(ALLOCATIONS!B4,MAPPING!$E$3:$G$302,3,FALSE)),"")) | E10: =IF(ALLOCATIONS!A4="","",ALLOCATIONS!C4) | F10: =IF(ALLOCATIONS!A4="","",IF(ALLOCATIONS!D4="",0,ALLOCATIONS!D4)) | G10: =IF(ALLOCATIONS!A4="","",SUMIFS(RAW_004!$I$2:$I$10001,RAW_004!$D$2:$D$10001,ALLOCATIONS!A4,RAW_004!$H$2:$H$10001,ALLOCATIONS!B4,RAW_004!$N$2:$N$10001,ALLOCATIONS!C4)) | H10: =IF(A10="","",G10-F10)
A11: =IF(ALLOCATIONS!A5="","",IFERROR(VLOOKUP(ALLOCATIONS!A5,MAPPING!$A$3:$C$302,2,FALSE),"UNMAPPED")) | B11: =IF(ALLOCATIONS!A5="","",IFERROR(VLOOKUP(ALLOCATIONS!A5,MAPPING!$A$3:$C$302,3,FALSE),ALLOCATIONS!A5)) | C11: =IF(ALLOCATIONS!A5="","",IFERROR(VLOOKUP(ALLOCATIONS!B5,MAPPING!$E$3:$G$302,2,FALSE),"UNMAPPED")) | D11: =IF(ALLOCATIONS!A5="","",IFERROR(IF(VLOOKUP(ALLOCATIONS!B5,MAPPING!$E$3:$G$302,3,FALSE)="","",VLOOKUP(ALLOCATIONS!B5,MAPPING!$E$3:$G$302,3,FALSE)),"")) | E11: =IF(ALLOCATIONS!A5="","",ALLOCATIONS!C5) | F11: =IF(ALLOCATIONS!A5="","",IF(ALLOCATIONS!D5="",0,ALLOCATIONS!D5)) | G11: =IF(ALLOCATIONS!A5="","",SUMIFS(RAW_004!$I$2:$I$10001,RAW_004!$D$2:$D$10001,ALLOCATIONS!A5,RAW_004!$H$2:$H$10001,ALLOCATIONS!B5,RAW_004!$N$2:$N$10001,ALLOCATIONS!C5)) | H11: =IF(A11="","",G11-F11)
A12: =IF(ALLOCATIONS!A6="","",IFERROR(VLOOKUP(ALLOCATIONS!A6,MAPPING!$A$3:$C$302,2,FALSE),"UNMAPPED")) | B12: =IF(ALLOCATIONS!A6="","",IFERROR(VLOOKUP(ALLOCATIONS!A6,MAPPING!$A$3:$C$302,3,FALSE),ALLOCATIONS!A6)) | C12: =IF(ALLOCATIONS!A6="","",IFERROR(VLOOKUP(ALLOCATIONS!B6,MAPPING!$E$3:$G$302,2,FALSE),"UNMAPPED")) | D12: =IF(ALLOCATIONS!A6="","",IFERROR(IF(VLOOKUP(ALLOCATIONS!B6,MAPPING!$E$3:$G$302,3,FALSE)="","",VLOOKUP(ALLOCATIONS!B6,MAPPING!$E$3:$G$302,3,FALSE)),"")) | E12: =IF(ALLOCATIONS!A6="","",ALLOCATIONS!C6) | F12: =IF(ALLOCATIONS!A6="","",IF(ALLOCATIONS!D6="",0,ALLOCATIONS!D6)) | G12: =IF(ALLOCATIONS!A6="","",SUMIFS(RAW_004!$I$2:$I$10001,RAW_004!$D$2:$D$10001,ALLOCATIONS!A6,RAW_004!$H$2:$H$10001,ALLOCATIONS!B6,RAW_004!$N$2:$N$10001,ALLOCATIONS!C6)) | H12: =IF(A12="","",G12-F12)
A13: =IF(ALLOCATIONS!A7="","",IFERROR(VLOOKUP(ALLOCATIONS!A7,MAPPING!$A$3:$C$302,2,FALSE),"UNMAPPED")) | B13: =IF(ALLOCATIONS!A7="","",IFERROR(VLOOKUP(ALLOCATIONS!A7,MAPPING!$A$3:$C$302,3,FALSE),ALLOCATIONS!A7)) | C13: =IF(ALLOCATIONS!A7="","",IFERROR(VLOOKUP(ALLOCATIONS!B7,MAPPING!$E$3:$G$302,2,FALSE),"UNMAPPED")) | D13: =IF(ALLOCATIONS!A7="","",IFERROR(IF(VLOOKUP(ALLOCATIONS!B7,MAPPING!$E$3:$G$302,3,FALSE)="","",VLOOKUP(ALLOCATIONS!B7,MAPPING!$E$3:$G$302,3,FALSE)),"")) | E13: =IF(ALLOCATIONS!A7="","",ALLOCATIONS!C7) | F13: =IF(ALLOCATIONS!A7="","",IF(ALLOCATIONS!D7="",0,ALLOCATIONS!D7)) | G13: =IF(ALLOCATIONS!A7="","",SUMIFS(RAW_004!$I$2:$I$10001,RAW_004!$D$2:$D$10001,ALLOCATIONS!A7,RAW_004!$H$2:$H$10001,ALLOCATIONS!B7,RAW_004!$N$2:$N$10001,ALLOCATIONS!C7)) | H13: =IF(A13="","",G13-F13)
A14: =IF(ALLOCATIONS!A8="","",IFERROR(VLOOKUP(ALLOCATIONS!A8,MAPPING!$A$3:$C$302,2,FALSE),"UNMAPPED")) | B14: =IF(ALLOCATIONS!A8="","",IFERROR(VLOOKUP(ALLOCATIONS!A8,MAPPING!$A$3:$C$302,3,FALSE),ALLOCATIONS!A8)) | C14: =IF(ALLOCATIONS!A8="","",IFERROR(VLOOKUP(ALLOCATIONS!B8,MAPPING!$E$3:$G$302,2,FALSE),"UNMAPPED")) | D14: =IF(ALLOCATIONS!A8="","",IFERROR(IF(VLOOKUP(ALLOCATIONS!B8,MAPPING!$E$3:$G$302,3,FALSE)="","",VLOOKUP(ALLOCATIONS!B8,MAPPING!$E$3:$G$302,3,FALSE)),"")) | E14: =IF(ALLOCATIONS!A8="","",ALLOCATIONS!C8) | F14: =IF(ALLOCATIONS!A8="","",IF(ALLOCATIONS!D8="",0,ALLOCATIONS!D8)) | G14: =IF(ALLOCATIONS!A8="","",SUMIFS(RAW_004!$I$2:$I$10001,RAW_004!$D$2:$D$10001,ALLOCATIONS!A8,RAW_004!$H$2:$H$10001,ALLOCATIONS!B8,RAW_004!$N$2:$N$10001,ALLOCATIONS!C8)) | H14: =IF(A14="","",G14-F14)
A15: =IF(ALLOCATIONS!A9="","",IFERROR(VLOOKUP(ALLOCATIONS!A9,MAPPING!$A$3:$C$302,2,FALSE),"UNMAPPED")) | B15: =IF(ALLOCATIONS!A9="","",IFERROR(VLOOKUP(ALLOCATIONS!A9,MAPPING!$A$3:$C$302,3,FALSE),ALLOCATIONS!A9)) | C15: =IF(ALLOCATIONS!A9="","",IFERROR(VLOOKUP(ALLOCATIONS!B9,MAPPING!$E$3:$G$302,2,FALSE),"UNMAPPED")) | D15: =IF(ALLOCATIONS!A9="","",IFERROR(IF(VLOOKUP(ALLOCATIONS!B9,MAPPING!$E$3:$G$302,3,FALSE)="","",VLOOKUP(ALLOCATIONS!B9,MAPPING!$E$3:$G$302,3,FALSE)),"")) | E15: =IF(ALLOCATIONS!A9="","",ALLOCATIONS!C9) | F15: =IF(ALLOCATIONS!A9="","",IF(ALLOCATIONS!D9="",0,ALLOCATIONS!D9)) | G15: =IF(ALLOCATIONS!A9="","",SUMIFS(RAW_004!$I$2:$I$10001,RAW_004!$D$2:$D$10001,ALLOCATIONS!A9,RAW_004!$H$2:$H$10001,ALLOCATIONS!B9,RAW_004!$N$2:$N$10001,ALLOCATIONS!C9)) | H15: =IF(A15="","",G15-F15)
A16: =IF(ALLOCATIONS!A10="","",IFERROR(VLOOKUP(ALLOCATIONS!A10,MAPPING!$A$3:$C$302,2,FALSE),"UNMAPPED")) | B16: =IF(ALLOCATIONS!A10="","",IFERROR(VLOOKUP(ALLOCATIONS!A10,MAPPING!$A$3:$C$302,3,FALSE),ALLOCATIONS!A10)) | C16: =IF(ALLOCATIONS!A10="","",IFERROR(VLOOKUP(ALLOCATIONS!B10,MAPPING!$E$3:$G$302,2,FALSE),"UNMAPPED")) | D16: =IF(ALLOCATIONS!A10="","",IFERROR(IF(VLOOKUP(ALLOCATIONS!B10,MAPPING!$E$3:$G$302,3,FALSE)="","",VLOOKUP(ALLOCATIONS!B10,MAPPING!$E$3:$G$302,3,FALSE)),"")) | E16: =IF(ALLOCATIONS!A10="","",ALLOCATIONS!C10) | F16: =IF(ALLOCATIONS!A10="","",IF(ALLOCATIONS!D10="",0,ALLOCATIONS!D10)) | G16: =IF(ALLOCATIONS!A10="","",SUMIFS(RAW_004!$I$2:$I$10001,RAW_004!$D$2:$D$10001,ALLOCATIONS!A10,RAW_004!$H$2:$H$10001,ALLOCATIONS!B10,RAW_004!$N$2:$N$10001,ALLOCATIONS!C10)) | H16: =IF(A16="","",G16-F16)
A17: =IF(ALLOCATIONS!A11="","",IFERROR(VLOOKUP(ALLOCATIONS!A11,MAPPING!$A$3:$C$302,2,FALSE),"UNMAPPED")) | B17: =IF(ALLOCATIONS!A11="","",IFERROR(VLOOKUP(ALLOCATIONS!A11,MAPPING!$A$3:$C$302,3,FALSE),ALLOCATIONS!A11)) | C17: =IF(ALLOCATIONS!A11="","",IFERROR(VLOOKUP(ALLOCATIONS!B11,MAPPING!$E$3:$G$302,2,FALSE),"UNMAPPED")) | D17: =IF(ALLOCATIONS!A11="","",IFERROR(IF(VLOOKUP(ALLOCATIONS!B11,MAPPING!$E$3:$G$302,3,FALSE)="","",VLOOKUP(ALLOCATIONS!B11,MAPPING!$E$3:$G$302,3,FALSE)),"")) | E17: =IF(ALLOCATIONS!A11="","",ALLOCATIONS!C11) | F17: =IF(ALLOCATIONS!A11="","",IF(ALLOCATIONS!D11="",0,ALLOCATIONS!D11)) | G17: =IF(ALLOCATIONS!A11="","",SUMIFS(RAW_004!$I$2:$I$10001,RAW_004!$D$2:$D$10001,ALLOCATIONS!A11,RAW_004!$H$2:$H$10001,ALLOCATIONS!B11,RAW_004!$N$2:$N$10001,ALLOCATIONS!C11)) | H17: =IF(A17="","",G17-F17)
A18: =IF(ALLOCATIONS!A12="","",IFERROR(VLOOKUP(ALLOCATIONS!A12,MAPPING!$A$3:$C$302,2,FALSE),"UNMAPPED")) | B18: =IF(ALLOCATIONS!A12="","",IFERROR(VLOOKUP(ALLOCATIONS!A12,MAPPING!$A$3:$C$302,3,FALSE),ALLOCATIONS!A12)) | C18: =IF(ALLOCATIONS!A12="","",IFERROR(VLOOKUP(ALLOCATIONS!B12,MAPPING!$E$3:$G$302,2,FALSE),"UNMAPPED")) | D18: =IF(ALLOCATIONS!A12="","",IFERROR(IF(VLOOKUP(ALLOCATIONS!B12,MAPPING!$E$3:$G$302,3,FALSE)="","",VLOOKUP(ALLOCATIONS!B12,MAPPING!$E$3:$G$302,3,FALSE)),"")) | E18: =IF(ALLOCATIONS!A12="","",ALLOCATIONS!C12) | F18: =IF(ALLOCATIONS!A12="","",IF(ALLOCATIONS!D12="",0,ALLOCATIONS!D12)) | G18: =IF(ALLOCATIONS!A12="","",SUMIFS(RAW_004!$I$2:$I$10001,RAW_004!$D$2:$D$10001,ALLOCATIONS!A12,RAW_004!$H$2:$H$10001,ALLOCATIONS!B12,RAW_004!$N$2:$N$10001,ALLOCATIONS!C12)) | H18: =IF(A18="","",G18-F18)
A19: =IF(ALLOCATIONS!A13="","",IFERROR(VLOOKUP(ALLOCATIONS!A13,MAPPING!$A$3:$C$302,2,FALSE),"UNMAPPED")) | B19: =IF(ALLOCATIONS!A13="","",IFERROR(VLOOKUP(ALLOCATIONS!A13,MAPPING!$A$3:$C$302,3,FALSE),ALLOCATIONS!A13)) | C19: =IF(ALLOCATIONS!A13="","",IFERROR(VLOOKUP(ALLOCATIONS!B13,MAPPING!$E$3:$G$302,2,FALSE),"UNMAPPED")) | D19: =IF(ALLOCATIONS!A13="","",IFERROR(IF(VLOOKUP(ALLOCATIONS!B13,MAPPING!$E$3:$G$302,3,FALSE)="","",VLOOKUP(ALLOCATIONS!B13,MAPPING!$E$3:$G$302,3,FALSE)),"")) | E19: =IF(ALLOCATIONS!A13="","",ALLOCATIONS!C13) | F19: =IF(ALLOCATIONS!A13="","",IF(ALLOCATIONS!D13="",0,ALLOCATIONS!D13)) | G19: =IF(ALLOCATIONS!A13="","",SUMIFS(RAW_004!$I$2:$I$10001,RAW_004!$D$2:$D$10001,ALLOCATIONS!A13,RAW_004!$H$2:$H$10001,ALLOCATIONS!B13,RAW_004!$N$2:$N$10001,ALLOCATIONS!C13)) | H19: =IF(A19="","",G19-F19)
... A1007: =IF(ALLOCATIONS!A1001="","",IFERROR(VLOOKUP(ALLOCATIONS!A1001,MAPPING!$A$3:$C$302,2,FALSE),"UNMAPPED")) | B1007: =IF(ALLOCATIONS!A1001="","",IFERROR(VLOOKUP(ALLOCATIONS!A1001,MAPPING!$A$3:$C$302,3,FALSE),ALLOCATIONS!A1001)) | C1007: =IF(ALLOCATIONS!A1001="","",IFERROR(VLOOKUP(ALLOCATIONS!B1001,MAPPING!$E$3:$G$302,2,FALSE),"UNMAPPED")) | D1007: =IF(ALLOCATIONS!A1001="","",IFERROR(IF(VLOOKUP(ALLOCATIONS!B1001,MAPPING!$E$3:$G$302,3,FALSE)="","",VLOOKUP(ALLOCATIONS!B1001,MAPPING!$E$3:$G$302,3,FALSE)),"")) | E1007: =IF(ALLOCATIONS!A1001="","",ALLOCATIONS!C1001) | F1007: =IF(ALLOCATIONS!A1001="","",IF(ALLOCATIONS!D1001="",0,ALLOCATIONS!D1001)) | G1007: =IF(ALLOCATIONS!A1001="","",SUMIFS(RAW_004!$I$2:$I$10001,RAW_004!$D$2:$D$10001,ALLOCATIONS!A1001,RAW_004!$H$2:$H$10001,ALLOCATIONS!B1001,RAW_004!$N$2:$N$10001,ALLOCATIONS!C1001)) | H1007: =IF(A1007="","",G1007-F1007)
